<?xml version="1.0" encoding="UTF-8"?>
<testng-results skipped="2" failed="2" ignored="0" total="12" passed="8">
  <reporter-output>
  </reporter-output>
  <suite name="Suite" duration-ms="445" started-at="2019-01-06T09:31:29Z" finished-at="2019-01-06T09:31:29Z">
    <groups>
    </groups>
    <test name="Test" duration-ms="445" started-at="2019-01-06T09:31:29Z" finished-at="2019-01-06T09:31:29Z">
      <class name="testngpackage.FirstClass">
        <test-method status="PASS" signature="four()[pri:0, instance:testngpackage.FirstClass@7c16905e]" name="four" duration-ms="16" started-at="2019-01-06T09:31:29Z" finished-at="2019-01-06T09:31:29Z">
          <reporter-output>
          </reporter-output>
        </test-method> <!-- four -->
        <test-method status="PASS" signature="one()[pri:0, instance:testngpackage.FirstClass@7c16905e]" name="one" duration-ms="16" started-at="2019-01-06T09:31:29Z" finished-at="2019-01-06T09:31:29Z">
          <reporter-output>
          </reporter-output>
        </test-method> <!-- one -->
        <test-method status="PASS" signature="three()[pri:0, instance:testngpackage.FirstClass@7c16905e]" name="three" duration-ms="0" started-at="2019-01-06T09:31:29Z" finished-at="2019-01-06T09:31:29Z">
          <reporter-output>
          </reporter-output>
        </test-method> <!-- three -->
        <test-method status="PASS" signature="two()[pri:0, instance:testngpackage.FirstClass@7c16905e]" name="two" duration-ms="0" started-at="2019-01-06T09:31:29Z" finished-at="2019-01-06T09:31:29Z">
          <reporter-output>
          </reporter-output>
        </test-method> <!-- two -->
      </class> <!-- testngpackage.FirstClass -->
      <class name="testngpackage.Second">
        <test-method status="PASS" signature="eight()[pri:0, instance:testngpackage.Second@1753acfe]" name="eight" duration-ms="15" started-at="2019-01-06T09:31:29Z" finished-at="2019-01-06T09:31:29Z">
          <reporter-output>
          </reporter-output>
        </test-method> <!-- eight -->
        <test-method status="PASS" signature="five()[pri:0, instance:testngpackage.Second@1753acfe]" name="five" duration-ms="0" started-at="2019-01-06T09:31:29Z" finished-at="2019-01-06T09:31:29Z">
          <reporter-output>
          </reporter-output>
        </test-method> <!-- five -->
        <test-method status="SKIP" signature="seven()[pri:0, instance:testngpackage.Second@1753acfe]" name="seven" duration-ms="0" started-at="2019-01-06T09:31:29Z" finished-at="2019-01-06T09:31:29Z">
          <exception class="org.testng.SkipException">
            <message>
              <![CDATA[error]]>
            </message>
            <full-stacktrace>
              <![CDATA[org.testng.SkipException: error
at testngpackage.Second.seven(Second.java:19)
at sun.reflect.NativeMethodAccessorImpl.invoke0(Native Method)
at sun.reflect.NativeMethodAccessorImpl.invoke(Unknown Source)
at sun.reflect.DelegatingMethodAccessorImpl.invoke(Unknown Source)
at java.lang.reflect.Method.invoke(Unknown Source)
at org.testng.internal.MethodInvocationHelper.invokeMethod(MethodInvocationHelper.java:124)
at org.testng.internal.Invoker.invokeMethod(Invoker.java:580)
at org.testng.internal.Invoker.invokeTestMethod(Invoker.java:716)
at org.testng.internal.Invoker.invokeTestMethods(Invoker.java:988)
at org.testng.internal.TestMethodWorker.invokeTestMethods(TestMethodWorker.java:125)
at org.testng.internal.TestMethodWorker.run(TestMethodWorker.java:109)
at org.testng.TestRunner.privateRun(TestRunner.java:648)
at org.testng.TestRunner.run(TestRunner.java:505)
at org.testng.SuiteRunner.runTest(SuiteRunner.java:455)
at org.testng.SuiteRunner.runSequentially(SuiteRunner.java:450)
at org.testng.SuiteRunner.privateRun(SuiteRunner.java:415)
at org.testng.SuiteRunner.run(SuiteRunner.java:364)
at org.testng.SuiteRunnerWorker.runSuite(SuiteRunnerWorker.java:52)
at org.testng.SuiteRunnerWorker.run(SuiteRunnerWorker.java:84)
at org.testng.TestNG.runSuitesSequentially(TestNG.java:1208)
at org.testng.TestNG.runSuitesLocally(TestNG.java:1137)
at org.testng.TestNG.runSuites(TestNG.java:1049)
at org.testng.TestNG.run(TestNG.java:1017)
at org.testng.remote.AbstractRemoteTestNG.run(AbstractRemoteTestNG.java:114)
at org.testng.remote.RemoteTestNG.initAndRun(RemoteTestNG.java:251)
at org.testng.remote.RemoteTestNG.main(RemoteTestNG.java:77)
]]>
            </full-stacktrace>
          </exception> <!-- org.testng.SkipException -->
          <reporter-output>
          </reporter-output>
        </test-method> <!-- seven -->
        <test-method status="SKIP" signature="six()[pri:0, instance:testngpackage.Second@1753acfe]" name="six" duration-ms="0" started-at="2019-01-06T09:31:29Z" finished-at="2019-01-06T09:31:29Z">
          <exception class="org.testng.SkipException">
            <message>
              <![CDATA[error]]>
            </message>
            <full-stacktrace>
              <![CDATA[org.testng.SkipException: error
at testngpackage.Second.six(Second.java:14)
at sun.reflect.NativeMethodAccessorImpl.invoke0(Native Method)
at sun.reflect.NativeMethodAccessorImpl.invoke(Unknown Source)
at sun.reflect.DelegatingMethodAccessorImpl.invoke(Unknown Source)
at java.lang.reflect.Method.invoke(Unknown Source)
at org.testng.internal.MethodInvocationHelper.invokeMethod(MethodInvocationHelper.java:124)
at org.testng.internal.Invoker.invokeMethod(Invoker.java:580)
at org.testng.internal.Invoker.invokeTestMethod(Invoker.java:716)
at org.testng.internal.Invoker.invokeTestMethods(Invoker.java:988)
at org.testng.internal.TestMethodWorker.invokeTestMethods(TestMethodWorker.java:125)
at org.testng.internal.TestMethodWorker.run(TestMethodWorker.java:109)
at org.testng.TestRunner.privateRun(TestRunner.java:648)
at org.testng.TestRunner.run(TestRunner.java:505)
at org.testng.SuiteRunner.runTest(SuiteRunner.java:455)
at org.testng.SuiteRunner.runSequentially(SuiteRunner.java:450)
at org.testng.SuiteRunner.privateRun(SuiteRunner.java:415)
at org.testng.SuiteRunner.run(SuiteRunner.java:364)
at org.testng.SuiteRunnerWorker.runSuite(SuiteRunnerWorker.java:52)
at org.testng.SuiteRunnerWorker.run(SuiteRunnerWorker.java:84)
at org.testng.TestNG.runSuitesSequentially(TestNG.java:1208)
at org.testng.TestNG.runSuitesLocally(TestNG.java:1137)
at org.testng.TestNG.runSuites(TestNG.java:1049)
at org.testng.TestNG.run(TestNG.java:1017)
at org.testng.remote.AbstractRemoteTestNG.run(AbstractRemoteTestNG.java:114)
at org.testng.remote.RemoteTestNG.initAndRun(RemoteTestNG.java:251)
at org.testng.remote.RemoteTestNG.main(RemoteTestNG.java:77)
]]>
            </full-stacktrace>
          </exception> <!-- org.testng.SkipException -->
          <reporter-output>
          </reporter-output>
        </test-method> <!-- six -->
      </class> <!-- testngpackage.Second -->
      <class name="testngpackage.Third">
        <test-method status="PASS" signature="anish()[pri:0, instance:testngpackage.Third@d2cc05a]" name="anish" duration-ms="53" started-at="2019-01-06T09:31:29Z" finished-at="2019-01-06T09:31:29Z">
          <reporter-output>
          </reporter-output>
        </test-method> <!-- anish -->
        <test-method status="FAIL" signature="eleven()[pri:0, instance:testngpackage.Third@d2cc05a]" name="eleven" duration-ms="15" started-at="2019-01-06T09:31:29Z" finished-at="2019-01-06T09:31:29Z">
          <exception class="java.lang.AssertionError">
            <message>
              <![CDATA[expected [ashish] but found [anish]]]>
            </message>
            <full-stacktrace>
              <![CDATA[java.lang.AssertionError: expected [ashish] but found [anish]
at org.testng.Assert.fail(Assert.java:96)
at org.testng.Assert.failNotEquals(Assert.java:776)
at org.testng.Assert.assertEqualsImpl(Assert.java:137)
at org.testng.Assert.assertEquals(Assert.java:118)
at org.testng.Assert.assertEquals(Assert.java:453)
at org.testng.Assert.assertEquals(Assert.java:463)
at testngpackage.Third.eleven(Third.java:11)
at sun.reflect.NativeMethodAccessorImpl.invoke0(Native Method)
at sun.reflect.NativeMethodAccessorImpl.invoke(Unknown Source)
at sun.reflect.DelegatingMethodAccessorImpl.invoke(Unknown Source)
at java.lang.reflect.Method.invoke(Unknown Source)
at org.testng.internal.MethodInvocationHelper.invokeMethod(MethodInvocationHelper.java:124)
at org.testng.internal.Invoker.invokeMethod(Invoker.java:580)
at org.testng.internal.Invoker.invokeTestMethod(Invoker.java:716)
at org.testng.internal.Invoker.invokeTestMethods(Invoker.java:988)
at org.testng.internal.TestMethodWorker.invokeTestMethods(TestMethodWorker.java:125)
at org.testng.internal.TestMethodWorker.run(TestMethodWorker.java:109)
at org.testng.TestRunner.privateRun(TestRunner.java:648)
at org.testng.TestRunner.run(TestRunner.java:505)
at org.testng.SuiteRunner.runTest(SuiteRunner.java:455)
at org.testng.SuiteRunner.runSequentially(SuiteRunner.java:450)
at org.testng.SuiteRunner.privateRun(SuiteRunner.java:415)
at org.testng.SuiteRunner.run(SuiteRunner.java:364)
at org.testng.SuiteRunnerWorker.runSuite(SuiteRunnerWorker.java:52)
at org.testng.SuiteRunnerWorker.run(SuiteRunnerWorker.java:84)
at org.testng.TestNG.runSuitesSequentially(TestNG.java:1208)
at org.testng.TestNG.runSuitesLocally(TestNG.java:1137)
at org.testng.TestNG.runSuites(TestNG.java:1049)
at org.testng.TestNG.run(TestNG.java:1017)
at org.testng.remote.AbstractRemoteTestNG.run(AbstractRemoteTestNG.java:114)
at org.testng.remote.RemoteTestNG.initAndRun(RemoteTestNG.java:251)
at org.testng.remote.RemoteTestNG.main(RemoteTestNG.java:77)
]]>
            </full-stacktrace>
          </exception> <!-- java.lang.AssertionError -->
          <reporter-output>
          </reporter-output>
        </test-method> <!-- eleven -->
        <test-method status="PASS" signature="gaurav()[pri:0, instance:testngpackage.Third@d2cc05a]" name="gaurav" duration-ms="15" started-at="2019-01-06T09:31:29Z" finished-at="2019-01-06T09:31:29Z">
          <reporter-output>
          </reporter-output>
        </test-method> <!-- gaurav -->
        <test-method status="FAIL" signature="nine()[pri:0, instance:testngpackage.Third@d2cc05a]" name="nine" duration-ms="63" started-at="2019-01-06T09:31:29Z" finished-at="2019-01-06T09:31:29Z">
          <exception class="java.lang.AssertionError">
            <message>
              <![CDATA[expected [ashish] but found [anish]]]>
            </message>
            <full-stacktrace>
              <![CDATA[java.lang.AssertionError: expected [ashish] but found [anish]
at org.testng.Assert.fail(Assert.java:96)
at org.testng.Assert.failNotEquals(Assert.java:776)
at org.testng.Assert.assertEqualsImpl(Assert.java:137)
at org.testng.Assert.assertEquals(Assert.java:118)
at org.testng.Assert.assertEquals(Assert.java:453)
at org.testng.Assert.assertEquals(Assert.java:463)
at testngpackage.Third.nine(Third.java:16)
at sun.reflect.NativeMethodAccessorImpl.invoke0(Native Method)
at sun.reflect.NativeMethodAccessorImpl.invoke(Unknown Source)
at sun.reflect.DelegatingMethodAccessorImpl.invoke(Unknown Source)
at java.lang.reflect.Method.invoke(Unknown Source)
at org.testng.internal.MethodInvocationHelper.invokeMethod(MethodInvocationHelper.java:124)
at org.testng.internal.Invoker.invokeMethod(Invoker.java:580)
at org.testng.internal.Invoker.invokeTestMethod(Invoker.java:716)
at org.testng.internal.Invoker.invokeTestMethods(Invoker.java:988)
at org.testng.internal.TestMethodWorker.invokeTestMethods(TestMethodWorker.java:125)
at org.testng.internal.TestMethodWorker.run(TestMethodWorker.java:109)
at org.testng.TestRunner.privateRun(TestRunner.java:648)
at org.testng.TestRunner.run(TestRunner.java:505)
at org.testng.SuiteRunner.runTest(SuiteRunner.java:455)
at org.testng.SuiteRunner.runSequentially(SuiteRunner.java:450)
at org.testng.SuiteRunner.privateRun(SuiteRunner.java:415)
at org.testng.SuiteRunner.run(SuiteRunner.java:364)
at org.testng.SuiteRunnerWorker.runSuite(SuiteRunnerWorker.java:52)
at org.testng.SuiteRunnerWorker.run(SuiteRunnerWorker.java:84)
at org.testng.TestNG.runSuitesSequentially(TestNG.java:1208)
at org.testng.TestNG.runSuitesLocally(TestNG.java:1137)
at org.testng.TestNG.runSuites(TestNG.java:1049)
at org.testng.TestNG.run(TestNG.java:1017)
at org.testng.remote.AbstractRemoteTestNG.run(AbstractRemoteTestNG.java:114)
at org.testng.remote.RemoteTestNG.initAndRun(RemoteTestNG.java:251)
at org.testng.remote.RemoteTestNG.main(RemoteTestNG.java:77)
]]>
            </full-stacktrace>
          </exception> <!-- java.lang.AssertionError -->
          <reporter-output>
          </reporter-output>
        </test-method> <!-- nine -->
      </class> <!-- testngpackage.Third -->
    </test> <!-- Test -->
  </suite> <!-- Suite -->
</testng-results>
